<?xml version="1.0" encoding="utf-8"?>
<!-- =================================================================================== -->
<!-- |    This document was autogenerated by xacro from engix.xacro                    | -->
<!-- |    EDITING THIS FILE BY HAND IS NOT RECOMMENDED                                 | -->
<!-- =================================================================================== -->
<robot name="engix">
  <material name="silver_default">
    <color rgba="0.700 0.700 0.700 1.000"/>
  </material>
  <material name="plate">
    <color rgba="0.3137254901960784 0.3137254901960784 0.3137254901960784 1.0"/>
  </material>
  <material name="paint_metallic_silver">
    <color rgba="0.984313725490196 0.9803921568627451 0.9607843137254902 1.0"/>
  </material>
  <material name="aluminum_satin">
    <color rgba="0.9607843137254902 0.9607843137254902 0.9647058823529412 1.0"/>
  </material>
  <!--https://wiki.ros.org/ros_control-->
  <transmission name="left_wheel_tran">
    <type>transmission_interface/SimpleTransmission</type>
    <joint name="left_wheel_joint">
      <hardwareInterface>hardware_interface/VelocityJointInterface</hardwareInterface>
    </joint>
    <actuator name="left_wheel_actr">
      <hardwareInterface>hardware_interface/VelocityJointInterface</hardwareInterface>
      <mechanicalReduction>1</mechanicalReduction>
    </actuator>
  </transmission>
  <transmission name="right_wheel_tran">
    <type>transmission_interface/SimpleTransmission</type>
    <joint name="right_wheel_joint">
      <hardwareInterface>hardware_interface/VelocityJointInterface</hardwareInterface>
    </joint>
    <actuator name="right_wheel_actr">
      <hardwareInterface>hardware_interface/VelocityJointInterface</hardwareInterface>
      <mechanicalReduction>1</mechanicalReduction>
    </actuator>
  </transmission>
  <gazebo>
    <plugin name="differential_drive_controller" filename="libgazebo_ros_diff_drive.so">
      <robotNamespace>/</robotNamespace>
      <legacyMode>true</legacyMode>
      <alwaysOn>true</alwaysOn>
      <publishWheelTF>false</publishWheelTF>
      <publishTf>1</publishTf>
      <publishOdomTF>true</publishOdomTF>
      <publishWheelJointState>true</publishWheelJointState>
      <updateRate>100.0</updateRate>
      <leftJoint>left_wheel_joint</leftJoint>
      <rightJoint>right_wheel_joint</rightJoint>
      <wheelSeparation>0.365</wheelSeparation>
      <wheelDiameter>0.156</wheelDiameter>
      <wheelAcceleration>1.0</wheelAcceleration>
      <wheelTorque>20</wheelTorque>
      <commandTopic>cmd_vel</commandTopic>
      <odometryTopic>odom</odometryTopic>
      <odometryFrame>odom</odometryFrame>
      <robotBaseFrame>base_link</robotBaseFrame>
      <odometrySource>world</odometrySource>
      <rosDebugLevel>na</rosDebugLevel>
    </plugin>
  </gazebo>
    <!-- <gazebo>
    <plugin filename="libgazebo_ros_control.so" name="gazebo_ros_control">
      <robotNamespace>/</robotNamespace>
      <legacyModeNS>true</legacyModeNS>
    </plugin>
  </gazebo> -->
  <gazebo reference="camera_depth_frame">
    <sensor name="camera" type="depth">
      <always_on>true</always_on>
      <update_rate>20.0</update_rate>
      <camera>
        <horizontal_fov>1.0471975512</horizontal_fov>
        <image>
          <format>B8G8R8</format>
          <width>640</width>
          <height>480</height>
        </image>
        <clip>
          <near>0.05</near>
          <far>8.0</far>
        </clip>
      </camera>
      <plugin filename="libgazebo_ros_openni_kinect.so" name="camera_depth_frame_kinect_controller">
        <robotNamespace>/</robotNamespace>
        <baseline>0.2</baseline>
        <alwaysOn>true</alwaysOn>
        <updateRate>0</updateRate>
        <cameraName>camera</cameraName>
        <imageTopicName>/camera/rgb/image_raw</imageTopicName>
        <cameraInfoTopicName>/camera/rgb/camera_info</cameraInfoTopicName>
        <depthImageTopicName>/camera/depth/image_raw</depthImageTopicName>
        <depthImageCameraInfoTopicName>/camera/depth/camera_info</depthImageCameraInfoTopicName>
        <pointCloudTopicName>/camera/depth/points</pointCloudTopicName>
        <frameName>camera_depth_optical_frame</frameName>
        <pointCloudCutoff>0.3</pointCloudCutoff>
        <distortion_k1>0.0</distortion_k1>
        <distortion_k2>0.0</distortion_k2>
        <distortion_k3>0.0</distortion_k3>
        <distortion_t1>0.0</distortion_t1>
        <distortion_t2>0.0</distortion_t2>
        <CxPrime>0</CxPrime>
        <Cx>0</Cx>
        <Cy>0</Cy>
        <focalLength>0</focalLength>
        <hackBaseline>0</hackBaseline>
      </plugin>
    </sensor>
  </gazebo>

<!-- <gazebo>
  <plugin name="p3d_base_controller" filename="libgazebo_ros_p3d.so">
    <alwaysOn>true</alwaysOn>
    <updateRate>50.0</updateRate>
    <bodyName>base_link</bodyName>
    <topicName>ground_truth/state</topicName>
    <gaussianNoise>0.01</gaussianNoise>
    <frameName>world</frameName>
    <xyzOffsets>0 0 0</xyzOffsets>
    <rpyOffsets>0 0 0</rpyOffsets>
  </plugin>
</gazebo> -->



<gazebo>
  <plugin name="differential_drive_controller" filename="libgazebo_ros_diff_drive.so">
    <robotNamespace>/</robotNamespace>
    <legacyMode>true</legacyMode>
    <alwaysOn>true</alwaysOn>
    <publishWheelTF>false</publishWheelTF>
    <publishOdomTF>true</publishOdomTF>
    <publishTf>true</publishTf>
    <publishWheelJointState>true</publishWheelJointState>
    <updateRate>100.0</updateRate>
    <leftJoint>left_wheel</leftJoint>
    <rightJoint>right_wheel</rightJoint>
    <wheelSeparation>0.365</wheelSeparation>
    <wheelDiameter>0.156</wheelDiameter>
    <wheelAcceleration>1.0</wheelAcceleration>
    <wheelTorque>20</wheelTorque>
    <commandTopic>cmd_vel</commandTopic>
    <odometryTopic>odom</odometryTopic>
    <odometryFrame>odom</odometryFrame>
    <robotBaseFrame>base_link</robotBaseFrame>
    <odometrySource>world</odometrySource>
    <rosDebugLevel>na</rosDebugLevel>
  </plugin>
</gazebo>
  <gazebo reference="laser_tof">
    <sensor name="laser_tof_sensor" type="ray" >
      <pose>0 0 0 0 0 0</pose>
      <visualize>false</visualize>
      <update_rate>20</update_rate>
      <ray>
        <scan>
          <horizontal>
            <samples>320</samples>
            <resolution>1</resolution>
            <min_angle>-0.66</min_angle>
            <max_angle>0.66</max_angle>
          </horizontal>
          <vertical>
            <samples>24</samples>
            <resolution>1</resolution>
            <min_angle>-0.045</min_angle>
            <max_angle>0.045</max_angle>
          </vertical>
        </scan>
        <range>
          <min>0.1</min>
          <max>4.0</max>
          <resolution>0.01</resolution>
        </range>
        <noise>
          <type>gaussian</type>
          <mean>0.0</mean>
          <stddev>0.01</stddev>
        </noise>
      </ray>
      <plugin name="gazebo_ros_laser_controller" filename="libgazebo_ros_velodyne_laser.so">
        <robotNamespace>/</robotNamespace>
        <topicName>ce30c_output</topicName>
        <frameName>laser_tof</frameName>
      </plugin>
    </sensor>
  </gazebo>
  <gazebo reference="laser">
    <sensor name="head_rplidar_sensor" type="ray">
      <pose>0 0 0.06 0 0 0</pose>
      <visualize>false</visualize>
      <update_rate>40</update_rate>
      <ray>
        <scan>
          <horizontal>
            <samples>720</samples>
            <resolution>1</resolution>
            <min_angle>-3.14159265</min_angle>
            <max_angle>3.14159265</max_angle>
          </horizontal>
        </scan>
        <range>
          <min>0.2</min>
          <max>7.0</max>
          <resolution>0.01</resolution>
        </range>
        <noise>
          <type>gaussian</type>
          <mean>0.0</mean>
          <stddev>0.01</stddev>
        </noise>
      </ray>
      <plugin filename="libgazebo_ros_laser.so" name="gazebo_ros_head_rplidar_controller">
        <topicName>scan</topicName>
        <frameName>laser</frameName>
      </plugin>
    </sensor>
  </gazebo>
  <!-- <gazebo>
    <plugin filename="libgazebo_ros_control.so" name="gazebo_ros_control">
      <robotNamespace>/</robotNamespace>
      <legacyModeNS>true</legacyModeNS>
    </plugin>
  </gazebo> -->

  <gazebo>
    <plugin filename="libgazebo_ros_imu.so" name="gazebo_imu_plugin">
      <robotNamespace>/</robotNamespace>
      <topicName>imu/data</topicName>
      <serviceName>imu_service</serviceName>
      <bodyName>base_link</bodyName>
      <gaussianNoise>0</gaussianNoise>
      <rpyOffsets>0 0 0</rpyOffsets>
      <updateRate>20.0</updateRate>
      <alwaysOn>true</alwaysOn>
    </plugin>
  </gazebo>
  <gazebo>
    <plugin filename="libhector_gazebo_ros_gps.so" name="gps_controller">
      <robotNamespace>/</robotNamespace>
      <updateRate>40</updateRate>
      <bodyName>base_link</bodyName>
      <frameId>base_link</frameId>
      <topicName>navsat/fix</topicName>
      <velocityTopicName>navsat/vel</velocityTopicName>
      <referenceLatitude>49.9</referenceLatitude>
      <referenceLongitude>8.9</referenceLongitude>
      <referenceHeading>0</referenceHeading>
      <referenceAltitude>0</referenceAltitude>
      <drift>0.0001 0.0001 0.0001</drift>
    </plugin>
  </gazebo>

  <!--
<gazebo reference="base_footprint">
  <material>Gazebo/Grey</material>
  <mu1>0.2</mu1>
  <mu2>0.2</mu2>
  <selfCollide>true</selfCollide>
  <gravity>true</gravity>
</gazebo>
-->
  <gazebo reference="base_link">
    <material>Gazebo/Grey</material>
    <!-- <mu1>0.0</mu1> -->
    <!-- <mu2>0.0</mu2> -->
    <!-- <selfCollide>true</selfCollide> -->
    <!-- <gravity>true</gravity> -->
  </gazebo>
  <gazebo reference="lwheel">
    <material>Gazebo/Black</material>
    <!-- <mu1>1.5</mu1> -->
    <!-- <mu2>1.5</mu2> -->
    <!-- <kp value="10000000.0"/> -->
    <!-- <kd value="10.0"/> -->
    <!-- <fdir1 value="1 0 0"/> -->
    <!-- <selfCollide>true</selfCollide> -->
  </gazebo>
  <gazebo reference="rwheel">
    <material>Gazebo/Black</material>
    <!-- <mu1>1.5</mu1> -->
    <!-- <mu2>1.5</mu2> -->
    <!-- <kp value="10000000.0"/> -->
    <!-- <kd value="10.0"/> -->
    <!-- <fdir1 value="1 0 0"/> -->
    <!-- <selfCollide>true</selfCollide> -->
  </gazebo>
  <gazebo reference="ZED2_1">
    <material>Gazebo/Black</material>
    <!-- <mu1>0.0</mu1> -->
    <!-- <mu2>0.0</mu2> -->
    <!-- <selfCollide>true</selfCollide> -->
  </gazebo>
  <gazebo reference="dc_dc_1">
    <material>Gazebo/Gray</material>
  </gazebo>
  <gazebo reference="battery_1">
    <material>Gazebo/Black</material>
  </gazebo>
  <gazebo reference="jetson_nano_1">
    <material>Gazebo/Green</material>
    <!-- <mu1>0.0</mu1> -->
    <!-- <mu2>0.0</mu2> -->
    <!-- <selfCollide>true</selfCollide> -->
  </gazebo>
  <gazebo reference="lan_1">
    <material>Gazebo/Gray</material>
  </gazebo>
  <gazebo reference="gps_1">
    <material>Gazebo/Green</material>
  </gazebo>
  <gazebo reference="laser">
    <material>Gazebo/Black</material>
  </gazebo>
  <gazebo reference="usb_hub_1">
    <material>Gazebo/Black</material>
  </gazebo>
  <gazebo reference="laser_tof">
    <material>Gazebo/Black</material>
  </gazebo>
  <gazebo reference="caster_right">
    <!-- <mu1>1.0</mu1> -->
    <!-- <mu2>1.0</mu2> -->
    <!-- <kp value="10000000.0"/> -->
    <!-- <kd value="1.0"/> -->
    <material>$Gazebo/Silver</material>
    <!-- <turnGravityOff>false</turnGravityOff> -->
    <!-- <selfCollide>true</selfCollide> -->
  </gazebo>
  <gazebo reference="caster_left">
    <!-- <mu1>1.0</mu1> -->
    <!-- <mu2>1.0</mu2> -->
    <!-- <kp value="10000000.0"/> -->
    <!-- <kd value="1.0"/> -->
    <material>Gazebo/Silver</material>
    <!-- <turnGravityOff>false</turnGravityOff> -->
    <!-- <selfCollide>true</selfCollide> -->
  </gazebo>
  <gazebo reference="caster_wheel_left">
    <!-- <mu1>1.0</mu1> -->
    <!-- <mu2>1.0</mu2> -->
    <!-- <kp value="10000000.0"/> -->
    <!-- <kd value="1.0"/> -->
    <!-- <fdir1 value="1 0 0"/> -->
    <material>Gazebo/Blue</material>
    <!-- <turnGravityOff>false</turnGravityOff> -->
    <!-- <selfCollide>true</selfCollide> -->
  </gazebo>
  <gazebo reference="caster_wheel_right">
    <!-- <mu1>1.0</mu1> -->
    <!-- <mu2>1.0</mu2> -->
    <!-- <kp value="10000000.0"/> -->
    <!-- <kd value="1.0"/> -->
    <!-- <fdir1 value="1 0 0"/> -->
    <material>Gazebo/Blue</material>
    <!-- <turnGravityOff>false</turnGravityOff> -->
    <!-- <selfCollide>true</selfCollide> -->
  </gazebo>
 
  
  <link name="base_footprint"/>
  <joint name="base_footprint_joint" type="fixed">
    <origin rpy="0 0 0" xyz="0 0 0"/>
    <parent link="base_link"/>
    <child link="base_footprint"/>
  </joint>
  <!--Inertial link stores the robot's inertial information !!!! RE_EDIT-->
  <link name="inertial_link">
    <inertial>
      <mass value="15.034"/>
      <origin xyz="0.0005263550102558459 -0.0008435206011111315 0.2088531479687758"/>
      <inertia ixx="0.298693" ixy="0.003154" ixz="-0.020052" iyy="0.45471" iyz="0.003425" izz="0.326894"/>
    </inertial>
  </link>
  <joint name="inertial_joint" type="fixed">
    <origin rpy="0 0 0" xyz="0 0 0"/>
    <parent link="base_link"/>
    <child link="inertial_link"/>
  </joint>
  <link name="base_link">
    <!--<inertial>
    <origin rpy="0 0 0" xyz="0.0005263550102558459 -0.0008435206011111315 0.2088531479687758"/>
    <mass value="15.0"/>
    <inertia ixx="0.298693" ixy="0.003154" ixz="-0.020052" iyy="0.45471" iyz="0.003425" izz="0.326894"/>
  </inertial> -->
    <visual>
      <origin rpy="0 0 0" xyz="0 0 0"/>
      <geometry>
        <mesh filename="package://engix_description/meshes/base_link.stl" scale="0.001 0.001 0.001"/>
      </geometry>
      <material name="silver_default"/>
    </visual>
    <collision>
      <origin rpy="0 0 0" xyz="0 0 0"/>
      <geometry>
        <mesh filename="package://engix_description/meshes/base_link.stl" scale="0.001 0.001 0.001"/>
      </geometry>
    </collision>
  </link>
  <link name="lwheel">
    <inertial>
      <origin rpy="0 0 0" xyz="9.457707256244063e-09 0.03585438960934953 7.241215550846114e-06"/>
      <mass value="2.5"/>
      <inertia ixx="0.001585" ixy="-0.0" ixz="0.0" iyy="0.002703" iyz="0.0" izz="0.001585"/>
    </inertial>
    <visual>
      <origin rpy="0 0 0" xyz="0.133355 -0.150817 -0.079162"/>
      <geometry>
        <mesh filename="package://engix_description/meshes/lwheel_1.stl" scale="0.001 0.001 0.001"/>
      </geometry>
      <material name="silver_default"/>
    </visual>
    <collision>
      <origin rpy="0 0 0" xyz="0.133355 -0.150817 -0.079162"/>
      <geometry>
        <mesh filename="package://engix_description/meshes/lwheel_1.stl" scale="0.001 0.001 0.001"/>
      </geometry>
    </collision>
  </link>
  <link name="rwheel">
    <inertial>
      <origin rpy="0 0 0" xyz="-6.147258196920191e-08 -0.035854161349757635 6.622358018903984e-06"/>
      <mass value="2.5"/>
      <inertia ixx="0.001585" ixy="-0.0" ixz="0.0" iyy="0.002703" iyz="-0.0" izz="0.001585"/>
    </inertial>
    <visual>
      <origin rpy="0 0 0" xyz="0.133355 0.146183 -0.079162"/>
      <geometry>
        <mesh filename="package://engix_description/meshes/rwheel_1.stl" scale="0.001 0.001 0.001"/>
      </geometry>
      <material name="silver_default"/>
    </visual>
    <collision>
      <origin rpy="0 0 0" xyz="0.133355 0.146183 -0.079162"/>
      <geometry>
        <mesh filename="package://engix_description/meshes/rwheel_1.stl" scale="0.001 0.001 0.001"/>
      </geometry>
    </collision>
  </link>
  <link name="ZED2_1">
    <!--<inertial>
    <origin rpy="0 0 0" xyz="-0.000581501231995768 -0.018000727408692088 0.014361531099989666"/>
    <mass value="0.15"/>
    <inertia ixx="0.002923" ixy="0.0" ixz="0.0" iyy="0.000179" iyz="-0.0" izz="0.002942"/>
  </inertial>-->
    <visual>
      <origin rpy="0 0 0" xyz="-0.176645 -0.00992 -0.4957"/>
      <geometry>
        <mesh filename="package://engix_description/meshes/ZED2_1.stl" scale="0.001 0.001 0.001"/>
      </geometry>
      <material name="plate"/>
    </visual>
    <!--<collision>
    <origin rpy="0 0 0" xyz="-0.176645 -0.00992 -0.4957"/>
    <geometry>
      <mesh filename="package://engix_description/meshes/ZED2_1.stl" scale="0.001 0.001 0.001"/>
    </geometry>
  </collision>-->
  </link>
  <link name="imu_link"/>
  <joint name="imu_joint" type="fixed">
    <parent link="base_link"/>
    <child link="imu_link"/>
    <origin rpy="0 0 0" xyz="0.176645 0.00992 0.4957"/>
  </joint>
  <link name="laser">
    <visual>
      <geometry>
        <cylinder length="0.04" radius="0.04"/>
      </geometry>
      <origin rpy="0 0 0" xyz="0 0 0"/>
      <material name="silver_default"/>
    </visual>
  </link>
  <link name="dc_dc_1">
    <visual>
      <origin rpy="0 0 0" xyz="-0.027645 0.10808 -0.2157"/>
      <geometry>
        <mesh filename="package://engix_description/meshes/dc_dc_1.stl" scale="0.001 0.001 0.001"/>
      </geometry>
      <material name="aluminum_satin"/>
    </visual>
  </link>
  <link name="battery_1">

    <visual>
      <origin rpy="0 0 0" xyz="-0.011102 -0.015765 -0.1077"/>
      <geometry>
        <mesh filename="package://engix_description/meshes/battery_1.stl" scale="0.001 0.001 0.001"/>
      </geometry>
      <material name="silver_default"/>
    </visual>
  </link>
  <link name="jetson_nano_1">
    <visual>
      <origin rpy="0 0 0" xyz="0.02108 -0.10192 -0.21904"/>
      <geometry>
        <mesh filename="package://engix_description/meshes/jetson_nano_1.stl" scale="0.001 0.001 0.001"/>
      </geometry>
      <material name="paint_metallic_silver"/>
    </visual>
  </link>
  <link name="lan_1">
    <visual>
      <origin rpy="0 0 0" xyz="-0.07857 -0.10192 -0.2157"/>
      <geometry>
        <mesh filename="package://engix_description/meshes/lan_1.stl" scale="0.001 0.001 0.001"/>
      </geometry>
      <material name="silver_default"/>
    </visual>
  </link>
  <link name="gps_1">
    <visual>
      <origin rpy="0 0 0" xyz="-0.112558 0.00808 -0.4957"/>
      <geometry>
        <mesh filename="package://engix_description/meshes/gps_1.stl" scale="0.001 0.001 0.001"/>
      </geometry>
      <material name="silver_default"/>
    </visual>
  </link>
  <link name="usb_hub_1">
    <visual>
      <origin rpy="0 0 0" xyz="0.077355 -0.00192 -0.3177"/>
      <geometry>
        <mesh filename="package://engix_description/meshes/usb_hub_1.stl" scale="0.001 0.001 0.001"/>
      </geometry>
      <material name="silver_default"/>
    </visual>
  </link>
  <link name="laser_tof">
    <visual>
      <origin rpy="0 0 0" xyz="-0.157645 0.04512 -0.3677"/>
      <geometry>
        <mesh filename="package://engix_description/meshes/lidar_tof_1.stl" scale="0.001 0.001 0.001"/>
      </geometry>
      <material name="silver_default"/>
    </visual>
    <collision>
      <origin rpy="0 0 0" xyz="-0.157645 0.04512 -0.3677"/>
      <geometry>
        <mesh filename="package://engix_description/meshes/lidar_tof_1.stl" scale="0.001 0.001 0.001"/>
      </geometry>
    </collision>
  </link>
  <link name="caster_right">
    <inertial>
      <origin rpy="0 0 0" xyz="-0.004690059190597118 -0.00031884478947080686 -0.01885204625585646"/>
      <mass value="0.3"/>
      <inertia ixx="2.5e-05" ixy="0.0" ixz="-6e-06" iyy="2.3e-05" iyz="0.0" izz="1.2e-05"/>
    </inertial>
    <visual>
      <origin rpy="0 0 0" xyz="-0.155465 0.084832 -0.072019"/>
      <geometry>
        <mesh filename="package://engix_description/meshes/caster_right_1.stl" scale="0.001 0.001 0.001"/>
      </geometry>
      <material name="silver_default"/>
    </visual>
    <collision>
      <origin rpy="0 0 0" xyz="-0.155465 0.084832 -0.072019"/>
      <geometry>
        <mesh filename="package://engix_description/meshes/caster_right_1.stl" scale="0.001 0.001 0.001"/>
      </geometry>
    </collision>
  </link>
  <link name="caster_left">
    <inertial>
      <origin rpy="0 0 0" xyz="-0.004690059190596646 -0.00031884478947068196 -0.01885204625585646"/>
      <mass value="0.3"/>
      <inertia ixx="2.5e-05" ixy="0.0" ixz="-6e-06" iyy="2.3e-05" iyz="0.0" izz="1.2e-05"/>
    </inertial>
    <visual>
      <origin rpy="0 0 0" xyz="-0.155465 -0.085168 -0.071999"/>
      <geometry>
        <mesh filename="package://engix_description/meshes/caster_left_1.stl" scale="0.001 0.001 0.001"/>
      </geometry>
      <material name="silver_default"/>
    </visual>
    <collision>
      <origin rpy="0 0 0" xyz="-0.155465 -0.085168 -0.071999"/>
      <geometry>
        <mesh filename="package://engix_description/meshes/caster_left_1.stl" scale="0.001 0.001 0.001"/>
      </geometry>
    </collision>
  </link>
  <link name="caster_wheel_left">
    <inertial>
      <origin rpy="0 0 0" xyz="1.9061138764597807e-07 0.0014995854065302239 1.7385093787486428e-07"/>
      <mass value="0.5"/>
      <inertia ixx="1.6e-05" ixy="-0.0" ixz="-0.0" iyy="2.9e-05" iyz="-0.0" izz="1.6e-05"/>
    </inertial>
    <visual>
      <origin rpy="0 0 0" xyz="-0.139465 -0.082668 -0.025999"/>
      <geometry>
        <mesh filename="package://engix_description/meshes/caster_wheel_left_1.stl" scale="0.001 0.001 0.001"/>
      </geometry>
      <material name="silver_default"/>
    </visual>
    <collision>
      <origin rpy="0 0 0" xyz="-0.139465 -0.082668 -0.025999"/>
      <geometry>
        <mesh filename="package://engix_description/meshes/caster_wheel_left_1.stl" scale="0.001 0.001 0.001"/>
      </geometry>
    </collision>
  </link>
  <link name="caster_wheel_right">
    <inertial>
      <origin rpy="0 0 0" xyz="1.905032832039133e-07 0.0014995854065301545 1.78805265319687e-07"/>
      <mass value="0.5"/>
      <inertia ixx="1.6e-05" ixy="0.0" ixz="0.0" iyy="2.9e-05" iyz="-0.0" izz="1.6e-05"/>
    </inertial>
    <visual>
      <origin rpy="0 0 0" xyz="-0.139465 0.087332 -0.026019"/>
      <geometry>
        <mesh filename="package://engix_description/meshes/caster_wheel_right_1.stl" scale="0.001 0.001 0.001"/>
      </geometry>
      <material name="silver_default"/>
    </visual>
    <collision>
      <origin rpy="0 0 0" xyz="-0.139465 0.087332 -0.026019"/>
      <geometry>
        <mesh filename="package://engix_description/meshes/caster_wheel_right_1.stl" scale="0.001 0.001 0.001"/>
      </geometry>
    </collision>
  </link>
  <link name="camera_link">
    <inertial>
      <mass value="0.001"/>
      <origin xyz="0 0 0"/>
      <inertia ixx="0.0001" ixy="0.0" ixz="0.0" iyy="0.0001" iyz="0.0" izz="0.0001"/>
    </inertial>
  </link>
  <link name="camera_rgb_frame">
    <inertial>
      <mass value="0.001"/>
      <origin xyz="0 0 0"/>
      <inertia ixx="0.0001" ixy="0.0" ixz="0.0" iyy="0.0001" iyz="0.0" izz="0.0001"/>
    </inertial>
  </link>
  <link name="camera_rgb_optical_frame"/>
  <link name="camera_depth_frame"/>
  <link name="camera_depth_optical_frame"/>
  <joint name="camera_rgb_joint" type="fixed">
    <origin rpy="0 0 0" xyz="0.176645 0.00992 0.4957"/>
    <parent link="base_link"/>
    <child link="camera_rgb_frame"/>
  </joint>
  <joint name="camera_rgb_optical_joint" type="fixed">
    <origin rpy="0 0 0" xyz="0.176645 0.00992 0.4957"/>
    <parent link="camera_rgb_frame"/>
    <child link="camera_rgb_optical_frame"/>
  </joint>
  <joint name="camera_joint" type="fixed">
    <origin rpy="0 0 0" xyz="0.176645 0.00992 0.4957"/>
    <parent link="camera_rgb_frame"/>
    <child link="camera_link"/>
  </joint>
  <joint name="camera_depth_joint" type="fixed">
    <origin rpy="0 0 0" xyz="0.176645 0.00992 0.4957"/>
    <parent link="camera_rgb_frame"/>
    <child link="camera_depth_frame"/>
  </joint>
  <joint name="camera_depth_optical_joint" type="fixed">
    <origin rpy="-1.5707 0 -1.5707" xyz="0.176645 0.00992 0.4957"/>
    <parent link="camera_depth_frame"/>
    <child link="camera_depth_optical_frame"/>
  </joint>

  <joint name="left_wheel" type="continuous">
    <origin rpy="0 0 0" xyz="-0.133355 0.150817 0.079162"/>
    <parent link="base_link"/>
    <child link="lwheel"/>
    <axis xyz="0.0 1.0 -0.0"/>
  </joint>
  <joint name="right_wheel_joint" type="continuous">
    <origin rpy="0 0 0" xyz="-0.133355 -0.146183 0.079162"/>
    <parent link="base_link"/>
    <child link="rwheel"/>
    <axis xyz="0.0 1.0 -0.0"/>
  </joint>
  <joint name="ZED2_joint" type="fixed">
    <origin rpy="0 0 0" xyz="0.176645 0.00992 0.4957"/>
    <parent link="base_link"/>
    <child link="ZED2_1"/>
  </joint>
  <joint name="dc_dc_joint" type="fixed">
    <origin rpy="0 0 0" xyz="0.027645 -0.10808 0.2157"/>
    <parent link="base_link"/>
    <child link="dc_dc_1"/>
  </joint>
  <joint name="battery_joint" type="fixed">
    <origin rpy="0 0 0" xyz="0.011102 0.015765 0.1077"/>
    <parent link="base_link"/>
    <child link="battery_1"/>
  </joint>
  <joint name="jetson_nano_joint" type="fixed">
    <origin rpy="0 0 0" xyz="-0.02108 0.10192 0.21904"/>
    <parent link="base_link"/>
    <child link="jetson_nano_1"/>
  </joint>
  <joint name="lan_joint" type="fixed">
    <origin rpy="0 0 0" xyz="0.07857 0.10192 0.2157"/>
    <parent link="base_link"/>
    <child link="lan_1"/>
  </joint>
  <joint name="gps_joint" type="fixed">
    <origin rpy="0 0 0" xyz="0.112558 -0.00808 0.4957"/>
    <parent link="base_link"/>
    <child link="gps_1"/>
  </joint>
  <joint name="usb_hub_joint" type="fixed">
    <origin rpy="0 0 0" xyz="-0.077355 0.00192 0.3177"/>
    <parent link="base_link"/>
    <child link="usb_hub_1"/>
  </joint>
  <joint name="laser_tof_joint" type="fixed">
    <origin rpy="0 0 0" xyz="0.157645 -0.04512 0.3677"/>
    <parent link="base_link"/>
    <child link="laser_tof"/>
  </joint>
  <joint name="caster_right_joint" type="continuous">
    <origin rpy="0 0 0" xyz="0.155465 -0.084832 0.072019"/>
    <parent link="base_link"/>
    <child link="caster_right"/>
    <axis xyz="0.0 0.0 -1.0"/>
  </joint>
  <joint name="caster_left_joint" type="continuous">
    <origin rpy="0 0 0" xyz="0.155465 0.085168 0.071999"/>
    <parent link="base_link"/>
    <child link="caster_left"/>
    <axis xyz="0.0 0.0 -1.0"/>
  </joint>
  <joint name="caster_wheel_left_joint" type="continuous">
    <origin rpy="0 0 0" xyz="-0.016 -0.0025 -0.046"/>
    <parent link="caster_left"/>
    <child link="caster_wheel_left"/>
    <axis xyz="-0.0 -1.0 0.0"/>
  </joint>
  <joint name="caster_wheel_right_joint" type="continuous">
    <origin rpy="0 0 0" xyz="-0.016 -0.0025 -0.046"/>
    <parent link="caster_right"/>
    <child link="caster_wheel_right"/>
    <axis xyz="-0.0 -1.0 0.0"/>
  </joint>
  <joint name="rp_laser_joint" type="fixed">
    <axis xyz="0 0 0"/>
    <origin rpy="0 0 0" xyz="0.086 -0.00908 0.5457"/>
    <parent link="base_link"/>
    <child link="laser"/>
  </joint>
</robot>
